Workbook

Sheet Read Me
B2: Central Kitchen — Online Delivery + Subscriptions Only
B3: No outlets, no franchise, no owned delivery fleet — one kitchen, two revenue streams
B6: WHAT CHANGED FROM THE OTHER MODELS
B7: • Back to ₹10L capital — this fits comfortably, with room to spare.
B8: • No retail outlets, no franchise — just the central kitchen and online orders (your own website/app/WhatsApp ordering, not a storefront).
B9: • No owned delivery fleet — riders are paid per delivery (gig/contract model), which keeps delivery a variable cost instead of a large upfront fleet purchase.
B10: • Two revenue streams modelled separately: one-off online orders, and weekly subscription meal plans (Starter/Balanced/Complete from your menu).
B12: THE HEADLINE
B13: Subscriptions carry a lower price per meal than one-off orders, but a noticeably better margin — because subscription deliveries batch efficiently (same rider, clustered drops, predictable routes), while one-off orders each need a dedicated trip. That's the main lever in this model.
B15: HOW THIS WORKBOOK WORKS
B16: 1. 'Assumptions' — capex, monthly fixed costs, per-order and per-subscription-meal unit economics, and separate ramp curves for one-off orders and subscription meals. All yellow cells are editable.
B17: 2. 'Monthly Projection' — 18 months, both revenue streams combined into one P&L with a running cash position.
... B28: Black text = formula, recalculates automatically

Sheet Assumptions
A1: Assumptions
A2: Every yellow cell feeds Monthly Projection and Daily P&L.
A4: TOTAL STARTING CAPITAL
A5: Total capital available | C5: 1000000
A7: ONE-TIME SETUP COSTS
A8: Item | C8: Amount (₹)
A9: Kitchen equipment (burners, fridge, blender, prep tables) | C9: 250000
A10: Kitchen fit-out (civil, electrical, plumbing) | C10: 150000
A11: Licenses & registration (FSSAI, GST, trade license) | C11: 40000
A12: Branding, menu design, initial packaging stock | C12: 60000
A13: Online ordering platform (website, WhatsApp ordering, basic app, payments) | C13: 150000
A14: Launch marketing campaign | C14: 80000
A15: Contingency / miscellaneous | C15: 50000
A16: Total setup cost | C16: =SUM(C9:C15) -> 780000
A17: Working capital buffer (remainder) | C17: =C5-C16 -> 220000
A19: MONTHLY FIXED OPERATING COSTS
A20: Item | C20: Amount (₹/month)
A21: Rent (kitchen only, no retail counter) | C21: 35000
A22: Staff — chef | C22: 22000
A23: Staff — 2 kitchen helpers | C23: 30000
A24: Staff — packing/dispatch coordinator | C24: 14000
A25: Staff — subscription/customer support (part-time) | C25: 10000
A26: Utilities (electricity, gas, water) | C26: 15000
A27: Ongoing marketing (digital ads, subscription acquisition) | C27: 18000
A28: Platform/tech maintenance (hosting, payment gateway) | C28: 8000
A29: Admin & accounting | C29: 7000
A30: Total fixed cost / month | C30: =SUM(C21:C29) -> 159000
A32: ONE-OFF ONLINE ORDERS — UNIT ECONOMICS
A33: Average order value (₹) | C33: 200
A34: Food cost / COGS (% of revenue) | C34: 0.3
A35: Delivery cost per order — dedicated trip (₹) | C35: 35
A37: SUBSCRIPTION MEALS — UNIT ECONOMICS
A38: Blended revenue per subscription meal (₹) | C38: 132
A39: Food cost / COGS (% of revenue) | C39: 0.3
A40: Delivery cost per meal — batched route (₹) | C40: 15
A42: RAMP — ONE-OFF ORDERS / DAY BY MONTH
A43: Month | B43: Orders / day
A44: Month 1 | B44: 15
A45: Month 2 | B45: 25
A46: Month 3 | B46: 35
...

Sheet Monthly Projection
A1: 18-Month Projection
A2: One-off orders and subscription meals combined into a single P&L.
A4: Month | B4: One-off orders/day | C4: Sub meals/day | D4: One-off revenue (₹) | E4: One-off contribution (₹) | F4: Sub revenue (₹) | G4: Sub contribution (₹) | H4: Total revenue (₹) | I4: Total contribution (₹) | J4: Fixed opex (₹) | K4: Net profit (₹) | L4: Cumulative net profit (₹) | M4: Cash position (₹) | N4: Op profit? | O4: Capital recovered?
A5: Month 1 | B5: =Assumptions!$B$44 -> 15 | C5: =Assumptions!$B$65 -> 10 | D5: =B5*30*Assumptions!$C$33 -> 90000 | E5: =D5-D5*Assumptions!$C$34-B5*30*Assumptions!$C$35 -> 47250 | F5: =C5*30*Assumptions!$C$38 -> 39600 | G5: =F5-F5*Assumptions!$C$39-C5*30*Assumptions!$C$40 -> 23220 | H5: =D5+F5 -> 129600 | I5: =E5+G5 -> 70470 | J5: =Assumptions!$C$30 -> 159000 | K5: =I5-J5 -> -88530 | L5: =K5 -> -88530 | M5: =Assumptions!$C$17+L5 -> 131470 | N5: =IF(K5>0,1,0) -> 0 | O5: =IF(L5>=Assumptions!$C$5,1,0) -> 0
A6: Month 2 | B6: =Assumptions!$B$45 -> 25 | C6: =Assumptions!$B$66 -> 20 | D6: =B6*30*Assumptions!$C$33 -> 150000 | E6: =D6-D6*Assumptions!$C$34-B6*30*Assumptions!$C$35 -> 78750 | F6: =C6*30*Assumptions!$C$38 -> 79200 | G6: =F6-F6*Assumptions!$C$39-C6*30*Assumptions!$C$40 -> 46440 | H6: =D6+F6 -> 229200 | I6: =E6+G6 -> 125190 | J6: =Assumptions!$C$30 -> 159000 | K6: =I6-J6 -> -33810 | L6: =L5+K6 -> -122340 | M6: =Assumptions!$C$17+L6 -> 97660 | N6: =IF(K6>0,1,0) -> 0 | O6: =IF(L6>=Assumptions!$C$5,1,0) -> 0
A7: Month 3 | B7: =Assumptions!$B$46 -> 35 | C7: =Assumptions!$B$67 -> 35 | D7: =B7*30*Assumptions!$C$33 -> 210000 | E7: =D7-D7*Assumptions!$C$34-B7*30*Assumptions!$C$35 -> 110250 | F7: =C7*30*Assumptions!$C$38 -> 138600 | G7: =F7-F7*Assumptions!$C$39-C7*30*Assumptions!$C$40 -> 81270 | H7: =D7+F7 -> 348600 | I7: =E7+G7 -> 191520 | J7: =Assumptions!$C$30 -> 159000 | K7: =I7-J7 -> 32520 | L7: =L6+K7 -> -89820 | M7: =Assumptions!$C$17+L7 -> 130180 | N7: =IF(K7>0,1,0) -> 1 | O7: =IF(L7>=Assumptions!$C$5,1,0) -> 0
A8: Month 4 | B8: =Assumptions!$B$47 -> 45 | C8: =Assumptions!$B$68 -> 50 | D8: =B8*30*Assumptions!$C$33 -> 270000 | E8: =D8-D8*Assumptions!$C$34-B8*30*Assumptions!$C$35 -> 141750 | F8: =C8*30*Assumptions!$C$38 -> 198000 | G8: =F8-F8*Assumptions!$C$39-C8*30*Assumptions!$C$40 -> 116100 | H8: =D8+F8 -> 468000 | I8: =E8+G8 -> 257850 | J8: =Assumptions!$C$30 -> 159000 | K8: =I8-J8 -> 98850 | L8: =L7+K8 -> 9030 | M8: =Assumptions!$C$17+L8 -> 229030 | N8: =IF(K8>0,1,0) -> 1 | O8: =IF(L8>=Assumptions!$C$5,1,0) -> 0
A9: Month 5 | B9: =Assumptions!$B$48 -> 55 | C9: =Assumptions!$B$69 -> 70 | D9: =B9*30*Assumptions!$C$33 -> 330000 | E9: =D9-D9*Assumptions!$C$34-B9*30*Assumptions!$C$35 -> 173250 | F9: =C9*30*Assumptions!$C$38 -> 277200 | G9: =F9-F9*Assumptions!$C$39-C9*30*Assumptions!$C$40 -> 162540 | H9: =D9+F9 -> 607200 | I9: =E9+G9 -> 335790 | J9: =Assumptions!$C$30 -> 159000 | K9: =I9-J9 -> 176790 | L9: =L8+K9 -> 185820 | M9: =Assumptions!$C$17+L9 -> 405820 | N9: =IF(K9>0,1,0) -> 1 | O9: =IF(L9>=Assumptions!$C$5,1,0) -> 0
A10: Month 6 | B10: =Assumptions!$B$49 -> 65 | C10: =Assumptions!$B$70 -> 90 | D10: =B10*30*Assumptions!$C$33 -> 390000 | E10: =D10-D10*Assumptions!$C$34-B10*30*Assumptions!$C$35 -> 204750 | F10: =C10*30*Assumptions!$C$38 -> 356400 | G10: =F10-F10*Assumptions!$C$39-C10*30*Assumptions!$C$40 -> 208980 | H10: =D10+F10 -> 746400 | I10: =E10+G10 -> 413730 | J10: =Assumptions!$C$30 -> 159000 | K10: =I10-J10 -> 254730 | L10: =L9+K10 -> 440550 | M10: =Assumptions!$C$17+L10 -> 660550 | N10: =IF(K10>0,1,0) -> 1 | O10: =IF(L10>=Assumptions!$C$5,1,0) -> 0
A11: Month 7 | B11: =Assumptions!$B$50 -> 72 | C11: =Assumptions!$B$71 -> 105 | D11: =B11*30*Assumptions!$C$33 -> 432000 | E11: =D11-D11*Assumptions!$C$34-B11*30*Assumptions!$C$35 -> 226800 | F11: =C11*30*Assumptions!$C$38 -> 415800 | G11: =F11-F11*Assumptions!$C$39-C11*30*Assumptions!$C$40 -> 243810 | H11: =D11+F11 -> 847800 | I11: =E11+G11 -> 470610 | J11: =Assumptions!$C$30 -> 159000 | K11: =I11-J11 -> 311610 | L11: =L10+K11 -> 752160 | M11: =Assumptions!$C$17+L11 -> 972160 | N11: =IF(K11>0,1,0) -> 1 | O11: =IF(L11>=Assumptions!$C$5,1,0) -> 0
A12: Month 8 | B12: =Assumptions!$B$51 -> 80 | C12: =Assumptions!$B$72 -> 120 | D12: =B12*30*Assumptions!$C$33 -> 480000 | E12: =D12-D12*Assumptions!$C$34-B12*30*Assumptions!$C$35 -> 252000 | F12: =C12*30*Assumptions!$C$38 -> 475200 | G12: =F12-F12*Assumptions!$C$39-C12*30*Assumptions!$C$40 -> 278640 | H12: =D12+F12 -> 955200 | I12: =E12+G12 -> 530640 | J12: =Assumptions!$C$30 -> 159000 | K12: =I12-J12 -> 371640 | L12: =L11+K12 -> 1123800 | M12: =Assumptions!$C$17+L12 -> 1343800 | N12: =IF(K12>0,1,0) -> 1 | O12: =IF(L12>=Assumptions!$C$5,1,0) -> 1
A13: Month 9 | B13: =Assumptions!$B$52 -> 80 | C13: =Assumptions!$B$73 -> 120 | D13: =B13*30*Assumptions!$C$33 -> 480000 | E13: =D13-D13*Assumptions!$C$34-B13*30*Assumptions!$C$35 -> 252000 | F13: =C13*30*Assumptions!$C$38 -> 475200 | G13: =F13-F13*Assumptions!$C$39-C13*30*Assumptions!$C$40 -> 278640 | H13: =D13+F13 -> 955200 | I13: =E13+G13 -> 530640 | J13: =Assumptions!$C$30 -> 159000 | K13: =I13-J13 -> 371640 | L13: =L12+K13 -> 1495440 | M13: =Assumptions!$C$17+L13 -> 1715440 | N13: =IF(K13>0,1,0) -> 1 | O13: =IF(L13>=Assumptions!$C$5,1,0) -> 1
A14: Month 10 | B14: =Assumptions!$B$53 -> 80 | C14: =Assumptions!$B$74 -> 120 | D14: =B14*30*Assumptions!$C$33 -> 480000 | E14: =D14-D14*Assumptions!$C$34-B14*30*Assumptions!$C$35 -> 252000 | F14: =C14*30*Assumptions!$C$38 -> 475200 | G14: =F14-F14*Assumptions!$C$39-C14*30*Assumptions!$C$40 -> 278640 | H14: =D14+F14 -> 955200 | I14: =E14+G14 -> 530640 | J14: =Assumptions!$C$30 -> 159000 | K14: =I14-J14 -> 371640 | L14: =L13+K14 -> 1867080 | M14: =Assumptions!$C$17+L14 -> 2087080 | N14: =IF(K14>0,1,0) -> 1 | O14: =IF(L14>=Assumptions!$C$5,1,0) -> 1
A15: Month 11 | B15: =Assumptions!$B$54 -> 80 | C15: =Assumptions!$B$75 -> 120 | D15: =B15*30*Assumptions!$C$33 -> 480000 | E15: =D15-D15*Assumptions!$C$34-B15*30*Assumptions!$C$35 -> 252000 | F15: =C15*30*Assumptions!$C$38 -> 475200 | G15: =F15-F15*Assumptions!$C$39-C15*30*Assumptions!$C$40 -> 278640 | H15: =D15+F15 -> 955200 | I15: =E15+G15 -> 530640 | J15: =Assumptions!$C$30 -> 159000 | K15: =I15-J15 -> 371640 | L15: =L14+K15 -> 2238720 | M15: =Assumptions!$C$17+L15 -> 2458720 | N15: =IF(K15>0,1,0) -> 1 | O15: =IF(L15>=Assumptions!$C$5,1,0) -> 1
A16: Month 12 | B16: =Assumptions!$B$55 -> 80 | C16: =Assumptions!$B$76 -> 120 | D16: =B16*30*Assumptions!$C$33 -> 480000 | E16: =D16-D16*Assumptions!$C$34-B16*30*Assumptions!$C$35 -> 252000 | F16: =C16*30*Assumptions!$C$38 -> 475200 | G16: =F16-F16*Assumptions!$C$39-C16*30*Assumptions!$C$40 -> 278640 | H16: =D16+F16 -> 955200 | I16: =E16+G16 -> 530640 | J16: =Assumptions!$C$30 -> 159000 | K16: =I16-J16 -> 371640 | L16: =L15+K16 -> 2610360 | M16: =Assumptions!$C$17+L16 -> 2830360 | N16: =IF(K16>0,1,0) -> 1 | O16: =IF(L16>=Assumptions!$C$5,1,0) -> 1
A17: Month 13 | B17: =Assumptions!$B$56 -> 80 | C17: =Assumptions!$B$77 -> 120 | D17: =B17*30*Assumptions!$C$33 -> 480000 | E17: =D17-D17*Assumptions!$C$34-B17*30*Assumptions!$C$35 -> 252000 | F17: =C17*30*Assumptions!$C$38 -> 475200 | G17: =F17-F17*Assumptions!$C$39-C17*30*Assumptions!$C$40 -> 278640 | H17: =D17+F17 -> 955200 | I17: =E17+G17 -> 530640 | J17: =Assumptions!$C$30 -> 159000 | K17: =I17-J17 -> 371640 | L17: =L16+K17 -> 2982000 | M17: =Assumptions!$C$17+L17 -> 3202000 | N17: =IF(K17>0,1,0) -> 1 | O17: =IF(L17>=Assumptions!$C$5,1,0) -> 1
A18: Month 14 | B18: =Assumptions!$B$57 -> 80 | C18: =Assumptions!$B$78 -> 120 | D18: =B18*30*Assumptions!$C$33 -> 480000 | E18: =D18-D18*Assumptions!$C$34-B18*30*Assumptions!$C$35 -> 252000 | F18: =C18*30*Assumptions!$C$38 -> 475200 | G18: =F18-F18*Assumptions!$C$39-C18*30*Assumptions!$C$40 -> 278640 | H18: =D18+F18 -> 955200 | I18: =E18+G18 -> 530640 | J18: =Assumptions!$C$30 -> 159000 | K18: =I18-J18 -> 371640 | L18: =L17+K18 -> 3353640 | M18: =Assumptions!$C$17+L18 -> 3573640 | N18: =IF(K18>0,1,0) -> 1 | O18: =IF(L18>=Assumptions!$C$5,1,0) -> 1
A19: Month 15 | B19: =Assumptions!$B$58 -> 80 | C19: =Assumptions!$B$79 -> 120 | D19: =B19*30*Assumptions!$C$33 -> 480000 | E19: =D19-D19*Assumptions!$C$34-B19*30*Assumptions!$C$35 -> 252000 | F19: =C19*30*Assumptions!$C$38 -> 475200 | G19: =F19-F19*Assumptions!$C$39-C19*30*Assumptions!$C$40 -> 278640 | H19: =D19+F19 -> 955200 | I19: =E19+G19 -> 530640 | J19: =Assumptions!$C$30 -> 159000 | K19: =I19-J19 -> 371640 | L19: =L18+K19 -> 3725280 | M19: =Assumptions!$C$17+L19 -> 3945280 | N19: =IF(K19>0,1,0) -> 1 | O19: =IF(L19>=Assumptions!$C$5,1,0) -> 1
A20: Month 16 | B20: =Assumptions!$B$59 -> 80 | C20: =Assumptions!$B$80 -> 120 | D20: =B20*30*Assumptions!$C$33 -> 480000 | E20: =D20-D20*Assumptions!$C$34-B20*30*Assumptions!$C$35 -> 252000 | F20: =C20*30*Assumptions!$C$38 -> 475200 | G20: =F20-F20*Assumptions!$C$39-C20*30*Assumptions!$C$40 -> 278640 | H20: =D20+F20 -> 955200 | I20: =E20+G20 -> 530640 | J20: =Assumptions!$C$30 -> 159000 | K20: =I20-J20 -> 371640 | L20: =L19+K20 -> 4096920 | M20: =Assumptions!$C$17+L20 -> 4316920 | N20: =IF(K20>0,1,0) -> 1 | O20: =IF(L20>=Assumptions!$C$5,1,0) -> 1
A21: Month 17 | B21: =Assumptions!$B$60 -> 80 | C21: =Assumptions!$B$81 -> 120 | D21: =B21*30*Assumptions!$C$33 -> 480000 | E21: =D21-D21*Assumptions!$C$34-B21*30*Assumptions!$C$35 -> 252000 | F21: =C21*30*Assumptions!$C$38 -> 475200 | G21: =F21-F21*Assumptions!$C$39-C21*30*Assumptions!$C$40 -> 278640 | H21: =D21+F21 -> 955200 | I21: =E21+G21 -> 530640 | J21: =Assumptions!$C$30 -> 159000 | K21: =I21-J21 -> 371640 | L21: =L20+K21 -> 4468560 | M21: =Assumptions!$C$17+L21 -> 4688560 | N21: =IF(K21>0,1,0) -> 1 | O21: =IF(L21>=Assumptions!$C$5,1,0) -> 1
A22: Month 18 | B22: =Assumptions!$B$61 -> 80 | C22: =Assumptions!$B$82 -> 120 | D22: =B22*30*Assumptions!$C$33 -> 480000 | E22: =D22-D22*Assumptions!$C$34-B22*30*Assumptions!$C$35 -> 252000 | F22: =C22*30*Assumptions!$C$38 -> 475200 | G22: =F22-F22*Assumptions!$C$39-C22*30*Assumptions!$C$40 -> 278640 | H22: =D22+F22 -> 955200 | I22: =E22+G22 -> 530640 | J22: =Assumptions!$C$30 -> 159000 | K22: =I22-J22 -> 371640 | L22: =L21+K22 -> 4840200 | M22: =Assumptions!$C$17+L22 -> 5060200 | N22: =IF(K22>0,1,0) -> 1 | O22: =IF(L22>=Assumptions!$C$5,1,0) -> 1

Sheet Daily P&L (At Maturity)
A1: Daily P&L — Once Both Streams Plateau
A2: Snapshot at Month 18 (last projected month).
A4: ONE-OFF ONLINE ORDERS
A5: Orders / day | C5: ='Monthly Projection'!B22 -> 80
A6: Daily revenue | C6: ='Monthly Projection'!D22/30 -> 16000
A7: Daily contribution (after food cost + delivery) | C7: ='Monthly Projection'!E22/30 -> 8400
A9: SUBSCRIPTION MEALS
A10: Meals / day | C10: ='Monthly Projection'!C22 -> 120
A11: Daily revenue | C11: ='Monthly Projection'!F22/30 -> 15840
A12: Daily contribution (after food cost + delivery) | C12: ='Monthly Projection'!G22/30 -> 9288
A14: FIXED COSTS
A15: Daily fixed costs (rent, staff, utilities, marketing, tech) | C15: =Assumptions!$C$30/30 -> 5300
A17: NET DAILY RESULT
A18: Total daily contribution (one-off + subscription) | C18: =C7+C12 -> 17688
A19: Less: daily fixed costs | C19: =-C15 -> -5300
A20: NET DAILY PROFIT | C20: =C18-C15 -> 12388

Sheet Break-Even Summary
A1: Break-Even Summary
A2: Headline numbers, pulled live from the projection.
A4: CAPITAL SPLIT
A5: Total capital | C5: =Assumptions!$C$5 -> 1000000
A6: One-time setup cost | C6: =Assumptions!$C$16 -> 780000
A7: Working capital buffer | C7: =Assumptions!$C$17 -> 220000
A9: DAILY RESULT AT MATURITY
A10: Net daily profit once both streams plateau | C10: ='Daily P&L (At Maturity)'!C20 -> 12388
A12: TIMELINE
A13: Month operations turn profitable | C13: =IFERROR("Month "&MATCH(1,'Monthly Projection'!N5:N22,0),"Not within 18 months") -> Month 3
A14: Month full ₹10L capital is recovered | C14: =IFERROR("Month "&MATCH(1,'Monthly Projection'!O5:O22,0),"Not within 18 months") -> Month 8
A16: WHY SUBSCRIPTIONS HELP
A17: One-off order contribution margin | C17: =('Daily P&L (At Maturity)'!C7)/('Daily P&L (At Maturity)'!C6) -> 0.525
A18: Subscription meal contribution margin | C18: =('Daily P&L (At Maturity)'!C12)/('Daily P&L (At Maturity)'!C11) -> 0.58636364
